OrderBookSim/OrderBookSim/Outputs/Output1361617609.txt
0,100,0,0,0
1,100,0,0,0
2,100,0,0,0
3,100,0,0,0
4,100,0,0,0
5,100,0,0,0
6,100,0,0,0
7,100,0,0,0
8,100,0,0,0
9,100,0,0,0
10,100,0,0,0
11,100,0,0,0
12,100,0,0,0
13,100,0,0,0
14,100,0,0,0
15,100,0,0,0
16,100,0,0,0
17,100,0,0,0
18,100,0,0,0
19,100,0,0,0
20,100,0,0,0
21,100,0,0,0
22,100,0,0,0
23,100,0,0,0
24,100,0,0,0
25,100,0,0,0
26,100,0,0,0
27,100,0,0,0
28,100,0,0,0
29,100,0,0,0
30,100,0,0,0
31,100,0,0,0
32,100,0,0,0
33,100,0,0,0
34,100,0,0,0
35,100,0,0,0
36,100,0,0,0
37,100,0,0,0
38,100,0,0,0
39,100,0,0,0
40,100,0,0,0
41,100,0,0,0
42,100,0,0,0
43,100,0,0,0
44,100,0,0,0
45,100,0,0,0
46,100,0,0,0
47,100,0,0,0
48,100,0,0,0
49,100,0,0,0
50,100,0,0,0
51,100,0,0,0
52,100,0,0,0
53,100,0,0,0
54,100,0,0,0
55,100,0,0,0
56,100,0,0,0
57,100,0,0,0
58,100,0,0,0
59,100,0,0,0
60,100,0,0,0
61,100,0,0,0
62,100,0,0,0
63,100,0,0,0
64,100,0,0,0
65,100,0,0,0
66,100,0,0,0
67,100,0,0,0
68,100,0,0,0
69,100,0,0,0
70,100,0,0,0
71,100,0,0,0
72,100,0,0,0
73,100,0,0,0
74,100,0,0,0
75,100,0,0,0
76,100,0,0,0
77,100,0,0,0
78,100,0,0,0
79,100,0,0,0
80,100,0,0,0
81,100,1,0,0
82,100,1,0,0
83,100,1,0,0
84,100,1,0,0
85,100,1,0,0
86,100,1,0,0
87,100,1,0,0
88,100,1,0,0
89,100,1,0,0
90,100,1,0,0
91,100,1,0,0
92,100,1,0,0
93,100,1,0,0
94,100,1,0,0
95,100,1,0,0
96,100,1,0,0
97,100,1,0,0
98,100,1,0,0
99,100,1,0,0
100,100,1,0,0
101,100,1,0,0
102,100,1,0,0
103,100,1,0,0
104,100,1,0,0
105,100,1,0,0
106,100,2,0,0
107,100,2,0,0
108,100,2,0,0
109,100,2,0,0
110,100,2,0,0
111,100,2,0,0
112,100,2,0,0
113,100,2,0,0
114,100,2,0,0
115,100,2,0,0
116,100,2,0,0
117,100,2,0,0
118,100,2,0,0
119,100,2,0,0
120,100,2,0,0
121,100,2,0,0
122,100,2,0,0
123,100,2,0,0
124,100,2,0,0
125,100,2,0,0
126,100,2,0,0
127,100,2,0,0
128,100,2,0,0
129,100,2,0,0
130,100,2,0,0
131,100,2,0,0
132,100,2,0,0
133,100,2,0,0
134,100,2,0,0
135,100,2,0,0
136,100,2,0,0
137,100,2,0,0
138,100,2,0,0
139,100,2,0,0
140,100,2,0,0
141,100,2,0,0
142,100,2,0,0
143,100,2,0,0
144,100,2,0,0
145,100,2,0,0
146,100,2,0,0
147,100,2,0,0
148,100,2,0,0
149,100,2,0,0
150,100,2,0,0
151,100,2,0,0
152,100,2,0,0
153,100,2,0,0
154,100,2,0,0
155,100,2,0,0
156,100,2,0,0
157,100,2,0,0
158,100,2,0,0
159,100,2,0,0
160,100,2,0,0
161,100,2,0,1
162,100,2,0,1
163,100,2,0,1
164,100,2,0,1
165,100,2,0,1
166,100,2,0,1
167,100,2,0,1
168,100,2,0,1
169,100,2,0,1
170,100,2,0,1
171,100,2,0,1
172,100,2,0,1
173,100,2,0,1
174,100,2,0,1
175,100,2,0,1
176,100,2,0,1
177,100,2,0,1
178,100,2,0,1
179,100,2,0,1
180,100,2,0,1
181,100,2,0,1
182,100,2,0,1
183,100,2,0,1
184,100,2,0,1
185,100,2,0,1
186,100,2,0,1
187,100,2,0,1
188,100,2,0,1
189,100,2,0,1
190,100,2,0,1
191,100,2,0,1
192,100,2,0,1
193,100,2,0,1
194,100,2,0,1
195,100,2,0,1
196,100,2,0,1
197,100,2,0,1
198,100,2,0,1
199,100,2,0,1
200,100,2,0,1
201,100,2,0,1
202,100,2,0,1
203,100,2,0,1
204,100,2,0,1
205,100,2,0,1
206,100,2,0,1
207,100,2,0,1
208,100,2,0,1
209,100,2,0,1
210,100,2,0,1
211,100,2,0,2
212,100,2,0,2
213,100,2,0,2
214,100,2,0,2
215,100,2,0,2
216,100,2,0,2
217,100,2,0,2
218,100,2,0,2
219,100,2,0,2
220,100,2,0,2
221,100,2,0,2
222,100,2,0,2
223,100,2,0,2
224,100,2,0,2
225,100,2,0,2
226,100,2,0,2
227,100,2,0,2
228,100,2,0,2
229,100,2,0,2
230,100,2,0,2
231,100,2,0,2
232,100,2,0,2
233,100,2,0,2
234,100,2,0,2
235,100,2,0,2
236,100,2,0,2
237,100,2,0,2
238,100,2,0,2
239,100,2,0,2
240,100,2,0,2
241,100,2,0,3
242,100,2,0,3
243,100,2,0,3
244,100,2,0,3
245,100,2,0,3
246,100,2,0,3
247,100,2,0,3
248,100,2,0,3
249,100,2,0,3
250,100,2,0,3
251,100,2,0,3
252,100,2,0,3
253,100,2,0,3
254,100,2,0,3
255,100,2,0,3
256,100,2,0,3
257,100,2,0,3
258,100,2,0,3
259,100,2,0,3
260,100,2,0,3
261,100,2,0,3
262,100,2,0,3
263,100,2,0,3
264,100,2,0,3
265,100,2,0,3
266,100,2,0,3
267,100,2,0,3
268,100,3,0,3
269,100,3,0,3
270,100,3,0,3
271,100,3,0,3
272,100,3,0,3
273,100,3,0,3
274,100,3,0,3
275,100,3,0,3
276,100,3,0,3
277,100,3,0,3
278,100,3,0,3
279,100,3,0,3
280,100,3,0,3
281,100,3,0,3
282,100,3,0,3
283,100,3,0,3
284,100,3,0,3
285,100,3,0,3
286,100,3,0,3
287,100,3,0,3
288,100,3,0,3
289,100,3,0,3
290,100,3,0,3
291,100,3,0,3
292,100,3,0,3
293,100,3,0,3
294,100,3,0,3
295,100,3,0,3
296,100,3,0,3
297,100,3,0,3
298,100,3,0,3
299,100,3,0,3
300,100,3,0,3
301,100,3,0,3
302,100,3,0,3
303,100,3,0,3
304,100,3,0,3
305,100,3,0,3
306,100,3,0,3
307,100,3,0,3
308,100,3,0,3
309,100,3,0,3
310,100,3,0,3
311,100,3,0,3
312,100,3,0,3
313,100,3,0,3
314,100,3,0,3
315,100,3,0,3
316,100,4,0,3
317,100,4,0,3
318,100,4,0,3
319,100,4,0,3
320,100,4,0,3
321,100,5,0,3
322,100,3,0,6
323,100,3,0,6
324,100,3,0,6
325,100,3,0,6
326,100,3,0,6
327,100,3,0,6
328,100,3,0,6
329,100,3,0,6
330,100,3,0,6
331,100,3,0,6
332,100,3,0,6
333,100,3,0,6
334,100,3,0,6
335,100,3,0,6
336,100,3,0,6
337,100,3,0,6
338,100,3,0,6
339,100,3,0,6
340,100,3,0,6
341,100,3,0,6
342,100,3,0,6
343,100,3,0,6
344,100,3,0,6
345,100,3,0,6
346,100,3,0,6
347,100,3,0,6
348,100,3,0,6
349,100,3,0,6
350,100,3,0,6
351,100,3,0,6
352,100,3,0,6
353,100,3,0,6
354,100,3,0,6
355,100,3,0,6
356,100,3,0,6
357,100,3,0,6
358,100,3,0,6
359,100,3,0,6
360,100,3,0,6
361,100,3,0,6
362,100,3,0,6
363,100,3,0,6
364,100,3,0,6
365,100,3,0,6
366,100,3,0,6
367,100,3,0,6
368,100,3,0,6
369,100,3,0,6
370,100,3,0,6
371,100,3,0,6
372,100,3,0,6
373,100,3,0,6
374,100,3,0,6
375,100,3,0,6
376,100,3,0,6
377,100,3,0,6
378,100,3,0,6
379,100,3,0,6
380,100,3,0,6
381,100,3,0,6
382,100,3,0,6
383,100,3,0,6
384,100,3,0,6
385,100,3,0,6
386,100,3,0,6
387,100,3,0,6
388,100,3,0,6
389,100,3,0,6
390,100,3,0,6
391,100,3,0,6
392,100,3,0,6
393,100,3,0,6
394,100,3,0,6
395,100,3,0,6
396,100,3,0,6
397,100,3,0,6
398,100,3,0,6
399,100,3,0,6
400,100,3,0,6
401,100,3,0,7
402,100,3,0,7
403,100,3,0,7
404,100,3,0,7
405,100,3,0,7
406,100,3,0,7
407,100,3,0,7
408,100,3,0,7
409,100,3,0,7
410,100,3,0,7
411,100,3,0,7
412,100,3,0,7
413,100,3,0,7
414,100,3,0,7
415,100,3,0,7
416,100,3,0,7
417,100,3,0,7
418,100,3,0,7
419,100,3,0,7
420,100,3,0,7
421,100.04,3,0,8
422,100.04,3,0,8
423,100.04,3,0,8
424,100.04,3,0,8
425,100.04,3,0,8
426,100.04,3,0,8
427,100.04,3,0,8
428,100.04,3,0,8
429,100.04,3,0,8
430,100.04,3,0,8
431,100.04,3,0,8
432,100.04,3,0,8
433,100.04,3,0,8
434,100.04,3,0,8
435,100.04,3,0,8
436,100.04,3,0,8
437,100.04,3,0,8
438,100.04,3,0,8
439,100.04,3,0,8
440,100.04,3,0,8
441,100.04,3,0,8
442,100.04,3,0,8
443,100.04,3,0,8
444,100.04,3,0,8
445,100.04,3,0,8
446,100.04,3,0,8
447,100.04,3,0,8
448,100.04,3,0,8
449,100.04,3,0,8
450,100.04,3,0,8
451,100.04,3,0,8
452,100.04,3,0,8
453,100.04,3,0,8
454,100.04,3,0,8
455,100.04,3,0,8
456,100.04,3,0,8
457,100.04,3,0,8
458,100.04,3,0,8
459,100.04,3,0,8
460,100.04,3,0,8
461,100.04,3,0,8
462,100.04,3,0,8
463,100.04,3,0,8
464,100.04,3,0,8
465,100.04,3,0,8
466,100.04,3,0,8
467,100.04,3,0,8
468,100.04,3,0,8
469,100.04,3,0,8
470,100.04,3,0,8
471,100.04,3,0,8
472,100.04,3,0,8
473,100.04,3,0,8
474,100.04,3,0,8
475,100.04,3,0,8
476,100.04,3,0,8
477,100.04,3,0,8
478,100.04,3,0,8
479,100.04,3,0,8
480,100.04,3,0,8
481,100.04,3,0,9
482,100.04,3,0,9
483,100.04,3,0,9
484,100.04,3,0,9
485,100.04,3,0,9
486,100.04,3,0,9
487,100.04,3,0,9
488,100.04,3,0,9
489,100.04,3,0,9
490,100.04,3,0,9
491,100.04,3,0,9
492,100.04,3,0,9
493,100.04,3,0,9
494,100.04,3,0,9
495,100.04,3,0,9
496,100.04,3,0,9
497,100.04,3,0,9
498,100.04,3,0,9
499,100.04,3,0,9
500,100.04,3,0,9
501,100.04,3,0,9
502,100.04,3,0,9
503,100.04,3,0,9
504,100.04,3,0,9
505,100.04,3,0,9
506,100.04,3,0,9
507,100.04,3,0,9
508,100.04,3,0,9
509,100.04,3,0,9
510,100.04,3,0,9
511,100.04,3,0,9
512,100.04,3,0,9
513,100.04,3,0,9
514,100.04,3,0,9
515,100.04,3,0,9
516,100.04,3,0,9
517,100.04,3,0,9
518,100.04,3,0,9
519,100.04,3,0,9
520,100.04,3,0,9
521,100.04,3,0,9
522,100.04,3,0,9
523,100.04,3,0,9
524,100.04,3,0,9
525,100.04,3,0,9
526,100.04,4,0,9
527,100.04,4,0,9
528,100.04,4,0,9
529,100.04,4,0,9
530,100.04,4,0,9
531,100.04,4,0,9
532,100.04,4,0,9
533,100.04,4,0,9
534,100.04,4,0,9
535,100.04,5,0,9
536,100.04,5,0,9
537,100.04,5,0,9
538,100.04,5,0,9
539,100.04,5,0,9
540,100.04,5,0,9
541,100.04,5,0,9
542,100.04,5,0,9
543,100.04,5,0,9
544,100.04,5,0,9
545,100.04,5,0,9
546,100.04,5,0,9
547,100.04,5,0,9
548,100.04,5,0,9
549,100.04,5,0,9
550,100.04,5,0,9
551,100.04,5,0,9
